Workbook

Sheet Order Tracking v3
A1: Account and Discount Information
A2: Vendor Name | B2: Username | C2: Password | D2: Discount % | E2: Tax Exempt? | K2: Notes
A3: GoBuilda | B3: dshunk@nd.edu | C3: Group09SeniorDesign$ | D3: 15 | E3: Yes | H3: Starting Amount | I3: =1000 -> 1000
A4: Adafruit | B4: Group09 or dshunk@nd.edu | C4: Group09SeniorDesign$ | D4: 10 | E4: Yes | H4: Amount Remaining on Card | I4: =I3-(F64) -> 307.38
A5: DigiKey | B5: dshunk@nd.edu | C5: Group09SeniorDesign$ | D5: No | E5: Yes | H5: Amount Remaining in Budget | I5: =I4-G64 -> 163.86
A6: Preliminary BOM
A7: Subassembly | B7: Name of part | C7: Amount Required | D7: Expected Unit price | E7: Expected Total Cost | F7: Total Cost | G7: Cost If Card Not Used (Components from EIH, ISALL, etc.) | H7: Date Ordered | I7: Receipt Link | J7: Delivered/Obtained? | K7: Link | L7: 3D printed, stock and manufacture, or final product? | M7: Notes
A8: Drivetrain | B8: 435 RPM GoBuilda Yellow Jacket Motors | C8: 2 | D8: 46.74 | E8: =C8*D8 -> 93.48 | F8: 93.48 | G8: 0 | H8: 45930 | I8: https://drive.google.com/drive/folders/1bpFnFNl3BLED7mmrxZh7vgY9uvHRqW9e | J8: Yes | K8: https://www.gobilda.com/5203-series-yellow-jacket-planetary-gear-motor-13-7-1-ratio-24mm-length-8mm-rex-shaft-435-rpm-3-3-5v-encoder/ | L8: Final product
B9: 1309 Series Sonic Hub (8mm REX™ Bore) | C9: 2 | D9: 6.79 | E9: =C9*D9 -> 13.58 | F9: 13.58 | G9: 0 | H9: 45930 | I9: https://drive.google.com/drive/folders/1bpFnFNl3BLED7mmrxZh7vgY9uvHRqW9e | J9: Yes | K9: https://www.gobilda.com/1309-series-sonic-hub-8mm-rex-bore/ | L9: Final product
B10: Hogback Traction Wheels (Back Wheels) | C10: 2 | D10: 8.49 | E10: =C10*D10 -> 16.98 | F10: 16.98 | G10: 0 | H10: 45930 | I10: https://drive.google.com/drive/folders/1bpFnFNl3BLED7mmrxZh7vgY9uvHRqW9e | J10: Yes | K10: https://www.gobilda.com/hogback-traction-wheel-96mm-diameter-50a-durometer/ | L10: Final product
B11: RoboClaw Motor Controller | C11: 1 | D11: 84.99 | E11: =C11*D11 -> 84.99 | F11: 84.99 | G11: 0 | H11: 45930 | I11: https://drive.google.com/drive/folders/1bpFnFNl3BLED7mmrxZh7vgY9uvHRqW9e | J11: Yes | K11: https://www.gobilda.com/roboclaw-2x15a-motor-controller/ | L11: Final product
B12: 2802 Series Zinc-Plated Steel Button Head Screw (M4 x 0.7mm, 12mm Length) - 25 Pack | C12: 2 | D12: 3.05 | E12: =C12*D12 -> 6.1 | F12: 6.1 | G12: 0 | H12: 45930 | I12: https://drive.google.com/drive/folders/1bpFnFNl3BLED7mmrxZh7vgY9uvHRqW9e | J12: Yes | K12: https://www.gobilda.com/2802-series-zinc-plated-steel-button-head-screw-m4-x-0-7mm-12mm-length-25-pack/ | L12: Final product
B13: 96mm Omni Wheel (14mm Bore, 50A Durometer) | C13: 2 | D13: 18.69 | E13: =C13*D13 -> 37.38 | F13: 0 | G13: 37.38 | H13: 45930 | I13: EIH | J13: Yes | K13: https://www.gobilda.com/96mm-omni-wheel-14mm-bore-50a-durometer/ | L13: Final product
B14: Raspberry Pi 4B | C14: 1 | D14: 59.99 | E14: =C14*D14 -> 59.99 | F14: 59.99 | G14: 0 | H14: 45932 | I14: https://drive.google.com/file/d/1jTrTnBhKoSQXvmdi0nXnZMtVRGH_JPNF/view?usp=sharing | J14: Yes | K14: https://www.amazon.com/Raspberry-Pi-Model-2GB/dp/B09TTNPB4J/ref=sr_1_7?crid=252TN1F58JG7S&dib=eyJ2IjoiMSJ9.HavuMzOx0pibLLpdWCmY0-n0KHJjeMikjbp58OMNJLHzsHsnrnftGjcbTUet3sVDtWfqXrWNT_k0tecU9w3FKXH2ovqggzRmNrAxzCSXAN4MIW-dVt4y_lBv65_4xWlpOFynxAc1vvqZbU0O4POhztxzEWIJLutZkLR7e5QKBxK0QEUaxvljbCqDhgi4j4SycpAX2ISoYqWR0d-ktpwasFRjYiY87Pt-06ZXpK3bbcK7ebo3Efmmhp7IM0G4TjF_fehxUl75SkZ0Lccy942LBsVlldwXyJJTAXj7OyNd4-Q.tSJdz6wDIH7He3vMiH1m9lPeU17o42S3eYchCjiuIN0&dib_tag=se&keywords=raspberry+pi+4b&qid=1758490404&s=electronics&sprefix=raspberry+pi+4b%2Celectronics%2C87&sr=1-7 | L14: Final product
B15: 12V NiMH Nested Battery (3000mAh, MH-FC XT30 Connector) | C15: 1 | D15: 55.24 | E15: =C15*D15 -> 55.24 | F15: 55.24 | G15: 0 | H15: 45932 | I15: https://drive.google.com/file/d/1bfNTbY0k-69QRZK7zLRSVl-RtCeFQFII/view?usp=sharing | J15: No | K15: https://www.gobilda.com/12v-nimh-nested-battery-3000mah-mh-fc-xt30-connector/ | L15: Final product
B16: SanDisk 64GB Ultra microSDXC UHS-I Memory Card with Adapter - Up to 140MB/s, C10, U1, Full HD, A1, MicroSD Card - SDSQUAB-064G-GN6MA [New Version] | C16: 1 | D16: 9.99 | E16: =C16*D16 -> 9.99 | F16: 9.82 | G16: 0 | H16: 45932 | I16: https://drive.google.com/file/d/1jTrTnBhKoSQXvmdi0nXnZMtVRGH_JPNF/view?usp=sharing | J16: Yes | K16: https://www.amazon.com/SanDisk-Ultra-microSDHC-Memory-Adapter/dp/B0B7NXBM6P/?th=1 | L16: Final Product
B17: Encoder Breakout Cable (4-Pos JST XH [MH-FC] to 4 x 1-Pos TJC8 [MH-FC], 300mm Length) | C17: 2 | D17: 3.39 | E17: 6.78 | F17: 6.78 | G17: 0 | H17: 45932 | I17: https://drive.google.com/file/d/1bfNTbY0k-69QRZK7zLRSVl-RtCeFQFII/view?usp=sharing | J17: Yes | K17: https://www.gobilda.com/encoder-breakout-cable-4-pos-jst-xh-mh-fc-to-4-x-1-pos-tjc8-mh-fc-300mm-length/?srsltid=AfmBOor2AVkUs5Vds3XKAik0pb3nAzGfoDlo60xQxr78PchH8gUdjScO | L17: Final Product
B18: 6mm 1611 Series Flanged Ball Bearing | C18: 1 | D18: 3.39 | E18: =C18*D18 -> 3.39 | F18: 3.39 | G18: 0 | H18: 45930 | I18: https://drive.google.com/drive/folders/1bpFnFNl3BLED7mmrxZh7vgY9uvHRqW9e | J18: Yes | K18: https://www.gobilda.com/1611-series-flanged-ball-bearing-6mm-id-x-14mm-od-5mm-thickness-2-pack/ | L18: Final product | M18: Need 2, but comes in a pack of 2
B19: 8mm 1611 Series Flanged Ball Bearing | C19: 1 | D19: 3.39 | E19: =C19*D19 -> 3.39 | F19: 3.39 | G19: 0 | H19: 45932 | I19: https://drive.google.com/file/d/1bfNTbY0k-69QRZK7zLRSVl-RtCeFQFII/view?usp=sharing | J19: Yes | K19: https://www.gobilda.com/1611-series-flanged-ball-bearing-8mm-id-x-14mm-od-5mm-thickness-2-pack/ | L19: Final product | M19: Need 2, but comes in a pack of 2
B20: 1201 Series Quad Block Pattern Mount (43-2) | C20: 2 | D20: 5.94 | E20: =C20*D20 -> 11.88 | F20: 11.88 | G20: 0 | H20: 45930 | I20: https://drive.google.com/drive/folders/1bpFnFNl3BLED7mmrxZh7vgY9uvHRqW9e | J20: Yes | K20: https://www.gobilda.com/1201-series-quad-block-pattern-mount-43-2/ | L20: Final product
B21: Shouldered 8mm REX™ Hub-Shaft (20mm Hub Offset) | C21: 2 | D21: 11.04 | E21: =C21*D21 -> 22.08 | F21: 22.08 | G21: 0 | H21: 45930 | I21: https://drive.google.com/drive/folders/1bpFnFNl3BLED7mmrxZh7vgY9uvHRqW9e | J21: Yes | K21: https://www.gobilda.com/shouldered-8mm-rex-hub-shaft-20mm-hub-offset/ | L21: Final product
B22: 5V battery pack | C22: 1 | D22: 18.69 | E22: =C22*D22 -> 18.69 | F22: 18.69 | G22: 0 | H22: 45939 | I22: https://drive.google.com/file/d/1fptz56D2GBNVqYwWAdK74m7UO4Xq7BUr/view?usp=sharing | J22: Yes | K22: https://www.amazon.com/dp/B0CB1FW5FC/ref=sspa_dk_detail_2?pd_rd_i=B0CB1FW5FC&pd_rd_w=yo3l8&content-id=amzn1.sym.bbb3fb5e-28ad-4062-a3ba-1f7b9f2e4371&pf_rd_p=bbb3fb5e-28ad-4062-a3ba-1f7b9f2e4371&pf_rd_r=881CYYGDW8VH1GFZ7ACS&pd_rd_wg=tVulY&pd_rd_r=80ab3d2b-1b78-405e-b51f-e282d9d62f99&sp_csd=d2lkZ2V0TmFtZT1zcF9kZXRhaWxfdGhlbWF0aWM&th=1 | L22: Final product
B23: USB - Micro USB | C23: 1 | D23: 4.99 | E23: 4.99 | F23: 4.99 | G23: 0 | H23: 45965 | I23: https://www.amazon.com/gp/product/B004GETLY2/ref=ox_sc_act_title_4?smid=A1OHX1ZYWFEJ99&psc=1 | J23: Yes
B24: BNO055 IMU Sensor | C24: 1 | D24: 34.95 | E24: 34.95 | F24: 0 | G24: 34.95 | H24: 45985 | I24: ISAL | J24: Yes | K24: https://www.adafruit.com/product/2472?srsltid=AfmBOoru6QF8aEFryTHnUaupkJaWuSUFJ5eSN-nVNmhKJTNAqOB8Qv5E | L24: Final Product
A25: Chassis | B25: 1120 Series U-Channel (9 Hole, 240mm Length) | C25: 4 | D25: 11.04 | E25: =C25*D25 -> 44.16 | F25: 44.16 | G25: 0 | H25: 45930 | I25: https://drive.google.com/drive/folders/1bpFnFNl3BLED7mmrxZh7vgY9uvHRqW9e | J25: Yes | K25: https://www.gobilda.com/1120-series-u-channel-9-hole-240mm-length/ | L25: Final Product
B26: M4 x 0.7mm Zinc-Plated Socket Head Screw (8mm Length) (25 Pack) | C26: 2 | D26: 2.71 | E26: =C26*D26 -> 5.42 | F26: 5.42 | G26: 0 | H26: 45930 | I26: https://drive.google.com/drive/folders/1bpFnFNl3BLED7mmrxZh7vgY9uvHRqW9e | J26: Yes | K26: https://www.gobilda.com/m4-x-0-7mm-zinc-plated-socket-head-screw-8mm-length/ | L26: Final Product
B27: M4 x 0.7mm Nylock Nut (25 Pack) | C27: 2 | D27: 2.54 | E27: =C27*D27 -> 5.08 | F27: 5.08 | G27: 0 | H27: 45930 | I27: https://drive.google.com/drive/folders/1bpFnFNl3BLED7mmrxZh7vgY9uvHRqW9e | J27: Yes | K27: https://www.gobilda.com/m4-x-0-7mm-nylock-nut/?sku=2812-0004-0007 | L27: Final Product
B28: 1123 Series Pattern Plate (1 x 7 Hole, 43 x 192mm) | C28: 1 | D28: 5.99 | E28: =C28*D28 -> 5.99 | F28: 5.09 | G28: 0 | H28: 45930 | I28: https://drive.google.com/drive/folders/1bpFnFNl3BLED7mmrxZh7vgY9uvHRqW9e | J28: Yes | K28: https://www.gobilda.com/1123-series-pattern-plate-1-x-7-hole-43-x-192mm/ | L28: Final Product
B29: 1106 Series Square Beam (13 Hole, 104mm Length) | C29: 2 | D29: 4.79 | E29: =C29*D29 -> 9.58 | F29: 8.14 | G29: 0 | H29: 45930 | I29: https://drive.google.com/drive/folders/1bpFnFNl3BLED7mmrxZh7vgY9uvHRqW9e | J29: Yes | K29: https://www.gobilda.com/1106-series-square-beam-13-hole-104mm-length/ | L29: Final Product
B30: 5 Pcs HC-SR04 Ultrasonic Sensor | C30: 1 | D30: 8.99 | E30: 8.99 | F30: 8.99 | G30: 0 | H30: 45932 | I30: https://drive.google.com/file/d/1jTrTnBhKoSQXvmdi0nXnZMtVRGH_JPNF/view?usp=sharing | J30: Yes | K30: https://www.amazon.com/dp/B01COSN7O6?ref=ppx_yo2ov_dt_b_fed_asin_title | L30: Final Product | M30: Pack of 5, we need 1
B31: Ultrasonic Sensor brackets | C31: 1 | D31: 6.99 | E31: =C31*D31 -> 6.99 | F31: 6.99 | G31: 0 | H31: 45939 | I31: https://drive.google.com/file/d/1fptz56D2GBNVqYwWAdK74m7UO4Xq7BUr/view?usp=sharing | J31: Yes | K31: https://www.amazon.com/MTDELE-HC-SR04-Ultrasonic-Arduino-Mounting/dp/B0D6WBK52V/ref=sr_1_2_sspa?crid=2O5U4GAP6ER8P&dib=eyJ2IjoiMSJ9.E2SIkElJhtFWCJCHL5Q6Yys8UWphh18sr7FUgRDIlqcCyuedPyWbrqpJTYjNpMds9SyGyrxxGSu9bRUioo0H9qyYqn2OXGinXZWJo2BZ-S5mwWIs7NSwcG3YPZHS6lEeSE6MOnweDrOgrNuivB7lkEdWe2mUt6x0XYv9k8mxCkkcMh1UcE_32MxSKXq9_yQb1WK4jhvmInMy5SwFlntCEFiY2VwlELgV7dX_EthoMFk.5VmuMnqg_PVZ-VkaZWrlmY7I4oGzCT-oVWZeOMu59Ic&dib_tag=se&keywords=ultrasonic+sensor&qid=1759414709&sprefix=ultrasonic+sens%2Caps%2C151&sr=8-2-spons&sp_csd=d2lkZ2V0TmFtZT1zcF9hdGY&psc=1 | L31: Final Product | M31: Pack of 5, we need 1
B32: 1/8 Inch Thick, 6" x 12" High Density Polyethylene White Plastic Sheet- Pack of 2 | C32: 1 | D32: 12.99 | E32: =C32*D32 -> 12.99 | F32: 12.99 | G32: 0 | H32: 45932 | I32: https://drive.google.com/file/d/1jTrTnBhKoSQXvmdi0nXnZMtVRGH_JPNF/view?usp=sharing | J32: Yes | K32: https://www.amazon.com/Bocolon-Density-Polyethylene-Plastic-Industry/dp/B0DBHFX4LB/ref=sr_1_1_sspa?crid=3DB0EZDRHAMPE&dib=eyJ2IjoiMSJ9.7rmP2iSG2yEj4I48OTV75PqkD6y8ja0Gd4dmq-mMSYnUZ0YAeMPIkyn2gACTVLFPY39IZj64Dq1eVe1aR5zm20oslYwDFtOB1KxKMDFTh1X-tQpz1rtq4qwienoAtvl83gtFk8B8MoUo4pg6EJxlxB4TLUgqYjNk2a7v3muaYc8z6wqgCQsvc2hqCg-GirjPKJSl1TdVhNb3LpAWy4g6cXf2n3DTD1nYialnFzz9RpE.lAUw60Gjyut-3JATGVuSuISxTzGXJFH12Y6KVHfSvcU&dib_tag=se&keywords=1%2F8%2Binch%2Bhdpe%2Bsheet&qid=1759414957&sprefix=1%2F8%2Binch%2Bhdpe%2Bsheet%2Caps%2C154&sr=8-1-spons&sp_csd=d2lkZ2V0TmFtZT1zcF9hdGY&th=1 | L32: Stock and Manufacture
B33: Hinge | C33: 1 | D33: 0.85 | E33: 0.85 | F33: 0 | G33: 0.85 | H33: 45967 | I33: EIH | J33: Yes | K33: https://www.amazon.com/Adiyer-Stainless-1-inch-Folding-Jewelry/dp/B08SJBD3L1?th=1 | L33: Final Product
B34: Corner Braces 25mm x 25mm 90 degree | C34: 7 | D34: 0.45 | E34: =C34*D34 -> 3.15 | F34: 0 | G34: =E34 -> 3.15 | H34: 45967 | I34: EIH | J34: Yes | K34: https://www.amazon.com/Bracket-Brackets-30x30mm-Stainless-Reinforce/dp/B07T9NG893?th=1 | L34: Final Product
B35: 1 in. Zinc-Plated Corner Brace | C35: 2 | D35: 0.44 | E35: =C35*D35 -> 0.88 | F35: 0 | G35: =E35 -> 0.88 | H35: 45939 | I35: EIH | J35: Yes | K35: Everbilt (20-Pack) 1 in. Zinc-Plated Corner Brace Value-Pack) 24487 - The Home Depot | L35: Product and Manufacture | M35: The brackets are originally 90 degrees and will be manufactured to reach the desired 127 degree angle
B36: White paints pens | C36: 1 | D36: 6.39 | E36: 7.99 | F36: 7.99 | G36: 0 | H36: 45986 | I36: amazon.com/gp/product/B0D21NHYX8/ref=ox_sc_act_title_1?smid=A2G79MFFPKHN4J&psc=1 | J36: Yes
B37: Acrylic Sheet | C37: 1 | D37: 15.78 | E37: =D37 -> 15.78 | F37: =E37 -> 15.78 | G37: 0 | H37: 45986 | I37: https://www.amazon.com/gp/product/B0CZ768K5Y/ref=ox_sc_act_title_2?smid=A128CO7G80NO6D&psc=1 | J37: Yes
B38: Sheet Material for covering | C38: 1 | D38: 17.99 | E38: =C38*D38 -> 17.99 | F38: 17.99 | G38: 0 | H38: 45958 | I38: https://www.amazon.com/gp/product/B0BJDKZWDF/ref=sw_img_1?smid=A34FLGFUMBB69H&th=1 | J38: Yes | K38: https://www.gobilda.com/shouldered-8mm-rex-hub-shaft-20mm-hub-offset/ | L38: Final product
B39: Laser Pointer | C39: 1 | D39: 9.49 | E39: 9.49 | F39: 9.49 | G39: 0 | H39: 45965 | I39: https://www.amazon.com/gp/product/B0DHZYM1JQ/ref=ox_sc_act_title_3?smid=A1FIU1KHKMEYGE&psc=1 | J39: Yes
A40: Pill Chamber | B40: TD-8125MG 25KG Digital Servo 360 Degree | C40: 1 | D40: 22.88 | E40: =C40*D40 -> 22.88 | F40: 22.88 | G40: 0 | H40: 45932 | I40: https://drive.google.com/file/d/1jTrTnBhKoSQXvmdi0nXnZMtVRGH_JPNF/view?usp=sharing | J40: Yes | K40: Amazon Link | L40: Final Product
...

Sheet Copy of Order Tracking v3
A1: Account and Discount Information
A2: Vendor Name | B2: Username | C2: Password | D2: Discount % | E2: Tax Exempt?
A3: GoBuilda | B3: dshunk@nd.edu | C3: Group09SeniorDesign$ | D3: 15 | E3: Yes | H3: Starting Amount | I3: =1000 -> 1000
A4: Adafruit | B4: Group09 or dshunk@nd.edu | C4: Group09SeniorDesign$ | D4: 10 | E4: Yes | H4: Amount Remaining on Card | I4: =I3-(F64) -> 307.38
A5: DigiKey | B5: dshunk@nd.edu | C5: Group09SeniorDesign$ | D5: No | E5: Yes | H5: Amount Remaining in Budget | I5: =I4-G64 -> 163.86
A6: BOM
A7: Subassembly | B7: Name of part | C7: Amount Required | D7: Expected Unit price | E7: Expected Total Cost | F7: Total Cost | G7: Cost If Card Not Used (Components from EIH, ISALL, etc.) | H7: Date Ordered | I7: Receipt Link | J7: Delivered/Obtained?
A8: Drivetrain | B8: 435 RPM GoBuilda Yellow Jacket Motors | C8: 2 | D8: 46.74 | E8: =C8*D8 -> 93.48 | F8: 93.48 | G8: 0 | H8: 45930 | I8: https://drive.google.com/drive/folders/1bpFnFNl3BLED7mmrxZh7vgY9uvHRqW9e | J8: Yes
B9: 1309 Series Sonic Hub (8mm REX™ Bore) | C9: 2 | D9: 6.79 | E9: =C9*D9 -> 13.58 | F9: 13.58 | G9: 0 | H9: 45930 | I9: https://drive.google.com/drive/folders/1bpFnFNl3BLED7mmrxZh7vgY9uvHRqW9e | J9: Yes
B10: Hogback Traction Wheels (Back Wheels) | C10: 2 | D10: 8.49 | E10: =C10*D10 -> 16.98 | F10: 16.98 | G10: 0 | H10: 45930 | I10: https://drive.google.com/drive/folders/1bpFnFNl3BLED7mmrxZh7vgY9uvHRqW9e | J10: Yes
B11: RoboClaw Motor Controller | C11: 1 | D11: 84.99 | E11: =C11*D11 -> 84.99 | F11: 84.99 | G11: 0 | H11: 45930 | I11: https://drive.google.com/drive/folders/1bpFnFNl3BLED7mmrxZh7vgY9uvHRqW9e | J11: Yes
B12: 2802 Series Zinc-Plated Steel Button Head Screw (M4 x 0.7mm, 12mm Length) - 25 Pack | C12: 2 | D12: 3.05 | E12: =C12*D12 -> 6.1 | F12: 6.1 | G12: 0 | H12: 45930 | I12: https://drive.google.com/drive/folders/1bpFnFNl3BLED7mmrxZh7vgY9uvHRqW9e | J12: Yes
B13: 96mm Omni Wheel (14mm Bore, 50A Durometer) | C13: 2 | D13: 18.69 | E13: =C13*D13 -> 37.38 | F13: 0 | G13: 37.38 | H13: 45930 | I13: EIH | J13: Yes
B14: Raspberry Pi 4B | C14: 1 | D14: 59.99 | E14: =C14*D14 -> 59.99 | F14: 59.99 | G14: 0 | H14: 45932 | I14: https://drive.google.com/file/d/1jTrTnBhKoSQXvmdi0nXnZMtVRGH_JPNF/view?usp=sharing | J14: Yes
B15: 12V NiMH Nested Battery (3000mAh, MH-FC XT30 Connector) | C15: 1 | D15: 55.24 | E15: =C15*D15 -> 55.24 | F15: 55.24 | G15: 0 | H15: 45932 | I15: https://drive.google.com/file/d/1bfNTbY0k-69QRZK7zLRSVl-RtCeFQFII/view?usp=sharing | J15: Yes
B16: SanDisk 64GB Ultra microSDXC UHS-I Memory Card with Adapter - Up to 140MB/s, C10, U1, Full HD, A1, MicroSD Card - SDSQUAB-064G-GN6MA [New Version] | C16: 1 | D16: 9.99 | E16: =C16*D16 -> 9.99 | F16: 9.82 | G16: 0 | H16: 45932 | I16: https://drive.google.com/file/d/1jTrTnBhKoSQXvmdi0nXnZMtVRGH_JPNF/view?usp=sharing | J16: Yes
B17: Encoder Breakout Cable (4-Pos JST XH [MH-FC] to 4 x 1-Pos TJC8 [MH-FC], 300mm Length) | C17: 2 | D17: 3.39 | E17: 6.78 | F17: 6.78 | G17: 0 | H17: 45932 | I17: https://drive.google.com/file/d/1bfNTbY0k-69QRZK7zLRSVl-RtCeFQFII/view?usp=sharing | J17: Yes
B18: 6mm 1611 Series Flanged Ball Bearing | C18: 1 | D18: 3.39 | E18: =C18*D18 -> 3.39 | F18: 3.39 | G18: 0 | H18: 45930 | I18: https://drive.google.com/drive/folders/1bpFnFNl3BLED7mmrxZh7vgY9uvHRqW9e | J18: Yes
B19: 8mm 1611 Series Flanged Ball Bearing | C19: 1 | D19: 3.39 | E19: =C19*D19 -> 3.39 | F19: 3.39 | G19: 0 | H19: 45932 | I19: https://drive.google.com/file/d/1bfNTbY0k-69QRZK7zLRSVl-RtCeFQFII/view?usp=sharing | J19: Yes
B20: 1201 Series Quad Block Pattern Mount (43-2) | C20: 2 | D20: 5.94 | E20: =C20*D20 -> 11.88 | F20: 11.88 | G20: 0 | H20: 45930 | I20: https://drive.google.com/drive/folders/1bpFnFNl3BLED7mmrxZh7vgY9uvHRqW9e | J20: Yes
B21: Shouldered 8mm REX™ Hub-Shaft (20mm Hub Offset) | C21: 2 | D21: 11.04 | E21: =C21*D21 -> 22.08 | F21: 22.08 | G21: 0 | H21: 45930 | I21: https://drive.google.com/drive/folders/1bpFnFNl3BLED7mmrxZh7vgY9uvHRqW9e | J21: Yes
B22: 5V battery pack | C22: 1 | D22: 18.69 | E22: =C22*D22 -> 18.69 | F22: 18.69 | G22: 0 | H22: 45939 | I22: https://drive.google.com/file/d/1fptz56D2GBNVqYwWAdK74m7UO4Xq7BUr/view?usp=sharing | J22: Yes
B23: USB - Micro USB | C23: 1 | D23: 4.99 | E23: 4.99 | F23: 4.99 | G23: 0 | H23: 45965 | I23: https://www.amazon.com/gp/product/B004GETLY2/ref=ox_sc_act_title_4?smid=A1OHX1ZYWFEJ99&psc=1 | J23: Yes
B24: BNO055 IMU Sensor | C24: 1 | D24: 34.95 | E24: 34.95 | F24: 0 | G24: 34.95 | H24: 45985 | I24: ISAL | J24: Yes
A25: Chassis | B25: 1120 Series U-Channel (9 Hole, 240mm Length) | C25: 4 | D25: 11.04 | E25: =C25*D25 -> 44.16 | F25: 44.16 | G25: 0 | H25: 45930 | I25: https://drive.google.com/drive/folders/1bpFnFNl3BLED7mmrxZh7vgY9uvHRqW9e | J25: Yes
B26: M4 x 0.7mm Zinc-Plated Socket Head Screw (8mm Length) (25 Pack) | C26: 2 | D26: 2.71 | E26: =C26*D26 -> 5.42 | F26: 5.42 | G26: 0 | H26: 45930 | I26: https://drive.google.com/drive/folders/1bpFnFNl3BLED7mmrxZh7vgY9uvHRqW9e | J26: Yes
B27: M4 x 0.7mm Nylock Nut (25 Pack) | C27: 2 | D27: 2.54 | E27: =C27*D27 -> 5.08 | F27: 5.08 | G27: 0 | H27: 45930 | I27: https://drive.google.com/drive/folders/1bpFnFNl3BLED7mmrxZh7vgY9uvHRqW9e | J27: Yes
B28: 1123 Series Pattern Plate (1 x 7 Hole, 43 x 192mm) | C28: 1 | D28: 5.99 | E28: =C28*D28 -> 5.99 | F28: 5.09 | G28: 0 | H28: 45930 | I28: https://drive.google.com/drive/folders/1bpFnFNl3BLED7mmrxZh7vgY9uvHRqW9e | J28: Yes
B29: 1106 Series Square Beam (13 Hole, 104mm Length) | C29: 2 | D29: 4.79 | E29: =C29*D29 -> 9.58 | F29: 8.14 | G29: 0 | H29: 45930 | I29: https://drive.google.com/drive/folders/1bpFnFNl3BLED7mmrxZh7vgY9uvHRqW9e | J29: Yes
B30: 5 Pcs HC-SR04 Ultrasonic Sensor | C30: 1 | D30: 8.99 | E30: 8.99 | F30: 8.99 | G30: 0 | H30: 45932 | I30: https://drive.google.com/file/d/1jTrTnBhKoSQXvmdi0nXnZMtVRGH_JPNF/view?usp=sharing | J30: Yes
B31: Ultrasonic Sensor brackets | C31: 1 | D31: 6.99 | E31: =C31*D31 -> 6.99 | F31: 6.99 | G31: 0 | H31: 45939 | I31: https://drive.google.com/file/d/1fptz56D2GBNVqYwWAdK74m7UO4Xq7BUr/view?usp=sharing | J31: Yes
B32: 1/8 Inch Thick, 6" x 12" High Density Polyethylene White Plastic Sheet- Pack of 2 | C32: 1 | D32: 12.99 | E32: =C32*D32 -> 12.99 | F32: 12.99 | G32: 0 | H32: 45932 | I32: https://drive.google.com/file/d/1jTrTnBhKoSQXvmdi0nXnZMtVRGH_JPNF/view?usp=sharing | J32: Yes
B33: Hinge | C33: 1 | D33: 0.85 | E33: 0.85 | F33: 0 | G33: 0.85 | H33: 45967 | I33: EIH | J33: Yes
B34: Corner Braces 25mm x 25mm 90 degree | C34: 7 | D34: 0.45 | E34: =C34*D34 -> 3.15 | F34: 0 | G34: =E34 -> 3.15 | H34: 45967 | I34: EIH | J34: Yes
B35: 1 in. Zinc-Plated Corner Brace | C35: 2 | D35: 0.44 | E35: =C35*D35 -> 0.88 | F35: 0 | G35: =E35 -> 0.88 | H35: 45939 | I35: EIH | J35: Yes
B36: White paints pens | C36: 1 | D36: 6.39 | E36: 7.99 | F36: 7.99 | G36: 0 | H36: 45986 | I36: amazon.com/gp/product/B0D21NHYX8/ref=ox_sc_act_title_1?smid=A2G79MFFPKHN4J&psc=1 | J36: Yes
B37: Acrylic Sheet | C37: 1 | D37: 15.78 | E37: =D37 -> 15.78 | F37: =E37 -> 15.78 | G37: 0 | H37: 45986 | I37: https://www.amazon.com/gp/product/B0CZ768K5Y/ref=ox_sc_act_title_2?smid=A128CO7G80NO6D&psc=1 | J37: Yes
B38: Sheet Material for covering | C38: 1 | D38: 17.99 | E38: =C38*D38 -> 17.99 | F38: 17.99 | G38: 0 | H38: 45958 | I38: https://www.amazon.com/gp/product/B0BJDKZWDF/ref=sw_img_1?smid=A34FLGFUMBB69H&th=1 | J38: Yes
B39: Laser Pointer | C39: 1 | D39: 9.49 | E39: 9.49 | F39: 9.49 | G39: 0 | H39: 45965 | I39: https://www.amazon.com/gp/product/B0DHZYM1JQ/ref=ox_sc_act_title_3?smid=A1FIU1KHKMEYGE&psc=1 | J39: Yes
A40: Pill Chamber | B40: TD-8125MG 25KG Digital Servo 360 Degree | C40: 1 | D40: 22.88 | E40: =C40*D40 -> 22.88 | F40: 22.88 | G40: 0 | H40: 45932 | I40: https://drive.google.com/file/d/1jTrTnBhKoSQXvmdi0nXnZMtVRGH_JPNF/view?usp=sharing | J40: Yes
...

Sheet Detailed BOM V1
A1: Preliminary BOM
A2: Subassembly | B2: Name of part | C2: Amount Required | D2: Unit price | E2: Total Cost | F2: Link | G2: 3D printed, stock and manufacture, or final product? | H2: Notes | I2: Order Status
A3: Drivetrain | B3: 435 RPM GoBuilda Yellow Jacket Motors | C3: 2 | D3: 54.99 | E3: =C3*D3 -> 109.98 | F3: https://www.gobilda.com/5203-series-yellow-jacket-planetary-gear-motor-13-7-1-ratio-24mm-length-8mm-rex-shaft-435-rpm-3-3-5v-encoder/ | G3: Final product | I3: ORDERED
B4: 1309 Series Sonic Hub (8mm REX™ Bore) | C4: 2 | D4: 7.99 | E4: =C4*D4 -> 15.98 | F4: https://www.gobilda.com/1309-series-sonic-hub-8mm-rex-bore/ | G4: Final product | I4: ORDERED | J4: 2
B5: Hogback Traction Wheels (Back Wheels) | C5: 2 | D5: 9.99 | E5: =C5*D5 -> 19.98 | F5: https://www.gobilda.com/hogback-traction-wheel-96mm-diameter-50a-durometer/ | G5: Final product | I5: ORDERED
B6: RoboClaw Motor Controller | C6: 1 | D6: 99.99 | E6: =C6*D6 -> 99.99 | F6: https://www.gobilda.com/roboclaw-2x15a-motor-controller/ | G6: Final product | I6: ORDERED | J6: 1
B7: 2802 Series Zinc-Plated Steel Button Head Screw (M4 x 0.7mm, 12mm Length) - 25 Pack | C7: 2 | D7: 3.59 | E7: =C7*D7 -> 7.18 | F7: https://www.gobilda.com/2802-series-zinc-plated-steel-button-head-screw-m4-x-0-7mm-12mm-length-25-pack/ | G7: Final product | I7: ORDERED | J7: 2
B8: 96mm Omni Wheels (Front Wheels) | C8: 2 | D8: 21.99 | E8: =C8*D8 -> 43.98 | F8: https://www.gobilda.com/96mm-omni-wheel-14mm-bore-50a-durometer/ | G8: Final product | I8: NOT YET
B9: Raspberry Pi 4B | C9: 1 | D9: 59.99 | E9: =C9*D9 -> 59.99 | F9: https://www.amazon.com/Raspberry-Pi-Model-2GB/dp/B09TTNPB4J/ref=sr_1_7?crid=252TN1F58JG7S&dib=eyJ2IjoiMSJ9.HavuMzOx0pibLLpdWCmY0-n0KHJjeMikjbp58OMNJLHzsHsnrnftGjcbTUet3sVDtWfqXrWNT_k0tecU9w3FKXH2ovqggzRmNrAxzCSXAN4MIW-dVt4y_lBv65_4xWlpOFynxAc1vvqZbU0O4POhztxzEWIJLutZkLR7e5QKBxK0QEUaxvljbCqDhgi4j4SycpAX2ISoYqWR0d-ktpwasFRjYiY87Pt-06ZXpK3bbcK7ebo3Efmmhp7IM0G4TjF_fehxUl75SkZ0Lccy942LBsVlldwXyJJTAXj7OyNd4-Q.tSJdz6wDIH7He3vMiH1m9lPeU17o42S3eYchCjiuIN0&dib_tag=se&keywords=raspberry+pi+4b&qid=1758490404&s=electronics&sprefix=raspberry+pi+4b%2Celectronics%2C87&sr=1-7 | G9: Final product | I9: NOT YET
B10: Recharable Battery (STILL TBD) | C10: 1 | D10: 23.99 | E10: =C10*D10 -> 23.99 | F10: https://www.horizonhobby.com/product/SPMX223S30.html?utm_source=google&utm_medium=cpc&utm_campaign=horizonhobby_shopping-catch-all_01_HIGH_NONBRAND&utm_campaignid=21803082141&adgroupid=177403203788&utm_content=717153848083&utm_term=::matchtype_&utm_campaign=horizonhobby_shopping-catch-all_01_HIGH_NONBRAND&utm_device=c&gad_source=1&gad_campaignid=21803082141&gbraid=0AAAAAD_XYFnlHiL7AuJt09DydfHVU8a5E&gclid=Cj0KCQjwxL7GBhDXARIsAGOcmIPf-NNGAqYpJERcda3UWFCJz1_7U0zTVIBhbQ2cUqwIIpjli_aaAZYaAhohEALw_wcB | G10: Final product | I10: NOT YET
B11: In-Line Fuse (STILL TBD) | C11: 1 | D11: 7.99 | E11: =C11*D11 -> 7.99 | F11: https://greatplainsindustries.com/products/15-amp-inline-blade-fuse-assembly?currency=USD&variant=45309174612203&utm_source=google&utm_medium=cpc&utm_campaign=Google%20Shopping&stkn=a58b0943c3a3&srsltid=AfmBOoqkjYlN-B0OjoPkA-O_3sAOCE-_kUCQOOv8S0REYq6af7ZgD4CSnPc | G11: Final Product | I11: NOT YET
B12: Raspberry Pi SD Card | C12: 1 | D12: 9.99 | E12: =C12*D12 -> 9.99 | F12: https://www.amazon.com/SanDisk-Ultra-microSDHC-Memory-Adapter/dp/B0B7NXBM6P/?th=1 | G12: Final Product | I12: NOT YET
B13: 6mm 1611 Series Flanged Ball Bearing | C13: 1 | D13: 3.99 | E13: =C13*D13 -> 3.99 | F13: https://www.gobilda.com/1611-series-flanged-ball-bearing-6mm-id-x-14mm-od-5mm-thickness-2-pack/ | G13: Final product | H13: Need 2, but comes in a pack of 2 | I13: ORDERED | J13: 1
B14: 8mm 1611 Series Flanged Ball Bearing | C14: 1 | D14: 8.99 | E14: =C14*D14 -> 8.99 | F14: GoBilda Original Amazon Link | G14: Final product | H14: Need 2, but comes in a pack of 2 | I14: NOT YET
B15: 1201 Series Quad Block Pattern Mount (43-2) | C15: 2 | D15: 6.99 | E15: =C15*D15 -> 13.98 | F15: https://www.gobilda.com/1201-series-quad-block-pattern-mount-43-2/ | G15: Final product | I15: ORDERED | J15: 2
B16: Shouldered 8mm REX™ Hub-Shaft (20mm Hub Offset) | C16: 2 | D16: 12.99 | E16: =C16*D16 -> 25.98 | F16: https://www.gobilda.com/shouldered-8mm-rex-hub-shaft-20mm-hub-offset/ | G16: Final product | I16: ORDERED | J16: 2
A17: Chassis | B17: 1120 Series U-Channel (9 Hole, 240mm Length) | C17: 4 | D17: 12.99 | E17: =C17*D17 -> 51.96 | F17: https://www.gobilda.com/1120-series-u-channel-9-hole-240mm-length/ | G17: Final Product | I17: ORDERED | J17: 4
B18: M4 x 0.7mm Zinc-Plated Socket Head Screw (8mm Length) (25 Pack) | C18: 2 | D18: 3.19 | E18: =C18*D18 -> 6.38 | F18: https://www.gobilda.com/m4-x-0-7mm-zinc-plated-socket-head-screw-8mm-length/ | G18: Final Product | I18: ORDERED | J18: 2
B19: 1123 Series Pattern Plate (1 x 7 Hole, 43 x 192mm) | C19: 1 | D19: 5.99 | E19: =C19*D19 -> 5.99 | F19: https://www.gobilda.com/1123-series-pattern-plate-1-x-7-hole-43-x-192mm/ | G19: Final Product | I19: ORDERED | J19: 2
B20: 1106 Series Square Beam (13 Hole, 104mm Length) | C20: 2 | D20: 4.79 | E20: =C20*D20 -> 9.58 | F20: https://www.gobilda.com/1106-series-square-beam-13-hole-104mm-length/ | G20: Final Product | I20: ORDERED
B21: 1/8 Inch Thick, 6" x 12" High Density Polyethylene White Plastic Sheet- Pack of 2 | C21: 1 | D21: 11.92 | E21: =C21*D21 -> 11.92 | F21: https://www.onlinemetals.com/en/buy/1-8-inch-thick%252c-6-x-12-high-density-polyethylene-white-plastic-sheet-pack-of-2/pid/mp-00028007?_gl=1*dlib3b*_up*MQ..*_ga*MTUwNzAyODgwMS4xNzU5MjQwNjQ1*_ga_C74B6845SE*czE3NTkyNDA2NDQkbzEkZzAkdDE3NTkyNDA2NDQkajYwJGwwJGgw*_ga_DC4616R96N*czE3NTkyNDA2NDQkbzEkZzAkdDE3NTkyNDA2NDQkajYwJGwwJGgw | G21: Stock and Manufacture | I21: NOT YET
B22: M4 x 0.7mm Nylock Nut (25 Pack) | C22: 2 | D22: 2.19 | E22: =C22*D22 -> 4.38 | F22: https://www.gobilda.com/m4-x-0-7mm-nylock-nut/?sku=2812-0004-0007 | G22: Final Product | I22: ORDERED | J22: 2
A23: Pill Chamber
B24: Parallax Feedback 360 Degree - High Speed Continuous Rotation Servo | C24: 1 | D24: 27.99 | E24: =C24*D24 -> 27.99 | F24: https://www.parallax.com/product/parallax-feedback-360-high-speed-servo/ | G24: Final Product | I24: NOT YET
B25: 2305 Series Brass, MOD 0.8, Servo Gear (25 Tooth Spline, 30 Tooth) | C25: 1 | D25: 9.99 | E25: =C25*D25 -> 9.99 | F25: https://www.gobilda.com/2305-series-brass-mod-0-8-servo-gear-25-tooth-spline-30-tooth/ | G25: Final Product | I25: ORDERED | J25: 1
B26: 20 Degree Pressure Angle Gear Rack, 32 Pitch (1 ft) | C26: 1 | D26: 3.87 | E26: =C26*D26 -> 3.87 | F26: 20 Degree Pressure Angle Gear Rack, 32 Pitch | McMaster-Carr | G26: Final Product | I26: NOT YET
B27: 3D Printing of tunnel and dispenser | C27: 1 | D27: 25 | E27: =C27*D27 -> 25 | F27: EIH (tentative to change) | G27: 3D Printed | H27: Possible plastic sheet. Use heat gun to mold into jelly bean chamber. | I27: NOT YET
B28: ABS Bar Stock (1 ft) | C28: 1 | D28: 4.8 | E28: =C28*D28 -> 4.8 | F28: https://www.mcmaster.com/8712K151-8712K152/ | G28: Stock and manufacture | I28: NOT YET
B29: PETE Polyethylene Terephthalate Jelly Bean Chambers | C29: 1 | D29: 8.54 | E29: =C29*D29 -> 8.54 | F29: amazon link | G29: Stock and manufacture | I29: NOT YET
A30: Koozie | B30: 3D printing with ABS-M30 | C30: 2 | D30: =25 -> 25 | E30: =C30*D30 -> 50 | I30: NOT YET
A31: Wearable Device
B32: Thermistors | C32: 2 | D32: 0.4 | E32: =C32*D32 -> 0.8 | F32: https://www.digikey.com/en/products/detail/kyocera-avx/ND03P00333K--/1452053?gad_source=1&gad_campaignid=20682862038&gbraid=0AAAAADrbLlihpozHczm7iSeXBJ4Rpn0DV&gclid=Cj0KCQjwxL7GBhDXARIsAGOcmIMkgYX8SvMh8Ca3dpat8Z4KVMCYqJJgqFAxlJ7ChvtwJ06sXMiWvT0aAoIHEALw_wcB&gclsrc=aw.ds | G32: Final Product | I32: NOT YET
B33: Button | C33: 2 | D33: 0.1 | E33: =C33*D33 -> 0.2 | F33: https://www.digikey.com/en/products/detail/omron-electronics-inc-emc-div/B3F-1020/44059?gclsrc=aw.ds&gad_source=1&gad_campaignid=20509826117&gbraid=0AAAAADrbLlgPahjgQjTiZA4NtmRxex-fT&gclid=Cj0KCQjwxL7GBhDXARIsAGOcmINhvAJ8CTcOZCDOgN0-hotT2-AahMXe-lMgYzgAD1VIPJNkVBgZdqYaAuCqEALw_wcB | G33: Final Product | I33: NOT YET
B34: Wiring | C34: 4 | D34: 0.82 | E34: =C34*D34 -> 3.28 | F34: https://www.digikey.com/en/products/detail/alpha-wire/5952-BK001/3714462?gclsrc=aw.ds&gad_source=1&gad_campaignid=22518511088&gbraid=0AAAAADrbLlhVhOLGFCPlUNazu0x0ttA0s&gclid=Cj0KCQjwxL7GBhDXARIsAGOcmIPyQ8hwEqQjQgVImE37vOKvKr1mWB6dPkPzyWkGeovws5WE5QfGTfEaAvJSEALw_wcB | G34: Final Product | I34: NOT YET
B35: Velcro Straps | C35: 1 | D35: 12.99 | E35: =C35*D35 -> 12.99 | F35: https://www.walmart.com/ip/10Pcs-Buddy-Tape-Finger-Straps-Hook-Loop-Splint-Washable-Reusable-Toe-Straighteners-Curled-Toes-Support-Black/17094772032?wmlspartner=wlpa&selectedSellerId=101044658&wmlspartner=wlpa&cn=FY25-ENTP-PMAX_cnv_dps_dsn_dis_ad_entp_e_n&gclsrc=aw.ds&adid=2222222229717094772032_101044658_0000000000_21407473164&wl0=&wl1=x&wl2=c&wl3=&wl4=&wl5=1017248&wl6=&wl7=&wl8=&wl9=pla&wl10=276374024&wl11=online&wl12=17094772032_101044658&veh=sem&gad_source=1&gad_campaignid=21690411341&gbraid=0AAAAADmfBIop_VMkZGxGUztXQNDLx5Xnb&gclid=Cj0KCQjw0NPGBhCDARIsAGAzpp09Hj-D8jirZ63Fy1QZetg9nVV2-cplttCXt_YcEuHNL-o4IEu5McAaAtNCEALw_wcB | G35: Stock | I35: NOT YET
B36: Nylon Webbing | C36: 1 | D36: 30 | E36: =C36*D36 -> 30 | F36: https://www.walmart.com/ip/Uxcell-Flat-Nylon-Webbing-Strap-2-Inch-20-Yards-Green-for-Backpack-Luggage-rack/937516920 | I36: NOT YET
B37: Ladder clasp | I37: NOT YET
B38: Build-A-Board ESP32-C3 | C38: 2 | D38: 20 | E38: =C38*D38 -> 40 | F38: Got from EIH | G38: Final Product | I38: NOT YET
B39: Battery to nano connector | C39: 1 | D39: 4.99 | E39: =C39*D39 -> 4.99 | F39: https://www.amazon.com/dp/B08SL9X2YC/ref=sspa_dk_detail_3?pd_rd_i=B08SL9X2YC&pd_rd_w=SXj0A&content-id=amzn1.sym.f2f1cf8f-cab4-44dc-82ba-0ca811fb90cc&pf_rd_p=f2f1cf8f-cab4-44dc-82ba-0ca811fb90cc&pf_rd_r=3F1J4HGH5R4GFFR52PH2&pd_rd_wg=WRLl2&pd_rd_r=332dadce-8055-49ea-95e9-0ac63b05240a&sp_csd=d2lkZ2V0TmFtZT1zcF9kZXRhaWxfdGhlbWF0aWM&th=1 | I39: NOT YET
B40: 9V Battery (4 pack) | C40: 1 | D40: 18.99 | E40: =C40*D40 -> 18.99 | F40: https://www.amazon.com/Quzmo-Rechargeable-Lithium-ion-Multimeters-Walkie-Talkie/dp/B0CRYBR876/ref=sr_1_6?dib=eyJ2IjoiMSJ9.AmbU2iWIJWmLrdxVTAnt282MGmjVjs086-2SWVfqZnUfPSwxeMfoGCBT6SzW_7msjsup7AEWUH9MjT7tZ4_8t0e9bolrgquHKyWZT5A79-VKktdHt-M5pSd1f2b24tdsbSC78NrPuV6_JL922AFxPWZNqUrCuq_hqDJ6fj46bDLilJ9e8B4Bfk9xByyp0NS6aKSSNoELk0ilNJu4eAaXr1C_sMkjAC1XTYVv4dyhExVyirpApBgoKmCeQK3opRM8v91XH6q70dIAgzv6DoR6nx5-5YE_TKO7Zjq-qrkVvdI.xeV7tGChITYND5UcpClBXA_y0Mxs-iZG48akDr7FHR4&dib_tag=se&keywords=9v%2Blithium%2Brechargeable%2Bbattery&qid=1758642638&sr=8-6&th=1 | G40: Final Product | I40: NOT YET
...

Sheet BOM With Discounts + Account In
A1: Account and Discount Information
A2: Vendor Name | B2: Username | C2: Password | D2: Discount % | E2: Tax Exempt? | F2: Notes
A3: GoBuilda | B3: dshunk@nd.edu | C3: Group09SeniorDesign$ | D3: 15 | E3: Yes, Applied
A4: Adafruit | B4: Group09 or dshunk@nd.edu | C4: Group09SeniorDesign$ | D4: Asked | E4: Yes, not yet submitted
A5: DigiKey | B5: dshunk@nd.edu | C5: Group09SeniorDesign$ | D5: No | E5: Yes, not yet submitted
A6: Preliminary BOM
A7: Subassembly | B7: Name of part | C7: Amount Required | D7: Unit price | E7: Total Cost | F7: Link | G7: 3D printed, stock and manufacture, or final product? | H7: Notes
A8: Drivetrain | B8: 435 RPM GoBuilda Yellow Jacket Motors | C8: 2 | D8: 46.74 | E8: =C8*D8 -> 93.48 | F8: https://www.gobilda.com/5203-series-yellow-jacket-planetary-gear-motor-13-7-1-ratio-24mm-length-8mm-rex-shaft-435-rpm-3-3-5v-encoder/ | G8: Final product
B9: Motor to Back Wheel Couplers | C9: 2 | D9: 6.79 | E9: =C9*D9 -> 13.58 | F9: https://www.gobilda.com/1309-series-sonic-hub-8mm-rex-bore/ | G9: Final product
B10: Hogback Traction Wheels (Back Wheels) | C10: 2 | D10: 8.49 | E10: =C10*D10 -> 16.98 | F10: https://www.gobilda.com/hogback-traction-wheel-96mm-diameter-50a-durometer/ | G10: Final product
B11: RoboClaw Motor Controller | C11: 1 | D11: 84.99 | E11: =C11*D11 -> 84.99 | F11: https://www.gobilda.com/roboclaw-2x15a-motor-controller/ | G11: Final product
B12: 2802 Series Zinc-Plated Steel Button Head Screw (M4 x 0.7mm, 12mm Length) - 25 Pack | C12: 2 | D12: 3.05 | E12: =C12*D12 -> 6.1 | F12: https://www.gobilda.com/2802-series-zinc-plated-steel-button-head-screw-m4-x-0-7mm-12mm-length-25-pack/ | G12: Final product
B13: 96mm Omni Wheels (Front Wheels) | C13: 2 | D13: 11.69 | E13: =C13*D13 -> 23.38 | F13: https://www.ebay.com/itm/165980580785 | G13: Final product
B14: Raspberry Pi 4B | C14: 1 | D14: 59.99 | E14: =C14*D14 -> 59.99 | F14: https://www.amazon.com/Raspberry-Pi-Model-2GB/dp/B09TTNPB4J/ref=sr_1_7?crid=252TN1F58JG7S&dib=eyJ2IjoiMSJ9.HavuMzOx0pibLLpdWCmY0-n0KHJjeMikjbp58OMNJLHzsHsnrnftGjcbTUet3sVDtWfqXrWNT_k0tecU9w3FKXH2ovqggzRmNrAxzCSXAN4MIW-dVt4y_lBv65_4xWlpOFynxAc1vvqZbU0O4POhztxzEWIJLutZkLR7e5QKBxK0QEUaxvljbCqDhgi4j4SycpAX2ISoYqWR0d-ktpwasFRjYiY87Pt-06ZXpK3bbcK7ebo3Efmmhp7IM0G4TjF_fehxUl75SkZ0Lccy942LBsVlldwXyJJTAXj7OyNd4-Q.tSJdz6wDIH7He3vMiH1m9lPeU17o42S3eYchCjiuIN0&dib_tag=se&keywords=raspberry+pi+4b&qid=1758490404&s=electronics&sprefix=raspberry+pi+4b%2Celectronics%2C87&sr=1-7 | G14: Final product
B15: Recharable Battery (STILL TBD) | C15: 1 | D15: 23.99 | E15: =C15*D15 -> 23.99 | F15: https://www.horizonhobby.com/product/SPMX223S30.html?utm_source=google&utm_medium=cpc&utm_campaign=horizonhobby_shopping-catch-all_01_HIGH_NONBRAND&utm_campaignid=21803082141&adgroupid=177403203788&utm_content=717153848083&utm_term=::matchtype_&utm_campaign=horizonhobby_shopping-catch-all_01_HIGH_NONBRAND&utm_device=c&gad_source=1&gad_campaignid=21803082141&gbraid=0AAAAAD_XYFnlHiL7AuJt09DydfHVU8a5E&gclid=Cj0KCQjwxL7GBhDXARIsAGOcmIPf-NNGAqYpJERcda3UWFCJz1_7U0zTVIBhbQ2cUqwIIpjli_aaAZYaAhohEALw_wcB | G15: Final product
B16: In-Line Fuse (STILL TBD) | C16: 1 | D16: 7.99 | E16: =C16*D16 -> 7.99 | F16: https://greatplainsindustries.com/products/15-amp-inline-blade-fuse-assembly?currency=USD&variant=45309174612203&utm_source=google&utm_medium=cpc&utm_campaign=Google%20Shopping&stkn=a58b0943c3a3&srsltid=AfmBOoqkjYlN-B0OjoPkA-O_3sAOCE-_kUCQOOv8S0REYq6af7ZgD4CSnPc | G16: Final Product
B17: Raspberry Pi SD Card | C17: 1 | D17: 9.99 | E17: =C17*D17 -> 9.99 | F17: https://www.amazon.com/SanDisk-Ultra-microSDHC-Memory-Adapter/dp/B0B7NXBM6P/?th=1 | G17: Final Product
B18: 6mm 1611 Series Flanged Ball Bearing | C18: 1 | D18: 3.39 | E18: =C18*D18 -> 3.39 | F18: https://www.gobilda.com/1611-series-flanged-ball-bearing-6mm-id-x-14mm-od-5mm-thickness-2-pack/ | G18: Final product | H18: Need 2, but comes in a pack of 2
B19: 8mm 1611 Series Flanged Ball Bearing | C19: 1 | D19: 3.39 | E19: =C19*D19 -> 3.39 | F19: https://www.gobilda.com/1611-series-flanged-ball-bearing-8mm-id-x-14mm-od-5mm-thickness-2-pack/ | G19: Final product | H19: Need 2, but comes in a pack of 2
B20: 1201 Series Quad Block Pattern Mount (43-2) | C20: 2 | D20: 5.94 | E20: =C20*D20 -> 11.88 | F20: https://www.gobilda.com/1201-series-quad-block-pattern-mount-43-2/ | G20: Final product
B21: Shouldered 8mm REX™ Hub-Shaft (20mm Hub Offset) | C21: 2 | D21: 11.04 | E21: =C21*D21 -> 22.08 | F21: https://www.gobilda.com/shouldered-8mm-rex-hub-shaft-20mm-hub-offset/ | G21: Final product
A22: Chassis | B22: 1120 Series U-Channel (9 Hole, 240mm Length) | C22: 4 | D22: 11.04 | E22: =C22*D22 -> 44.16 | F22: https://www.gobilda.com/1120-series-u-channel-9-hole-240mm-length/ | G22: Final Product
B23: M4 x 0.7mm Zinc-Plated Socket Head Screw (8mm Length) (25 Pack) | C23: 2 | D23: 2.71 | E23: =C23*D23 -> 5.42 | F23: https://www.gobilda.com/m4-x-0-7mm-zinc-plated-socket-head-screw-8mm-length/ | G23: Final Product
B24: M4 x 0.7mm Nylock Nut (25 Pack) | C24: 2 | D24: 2.54 | E24: =C24*D24 -> 5.08 | F24: https://www.gobilda.com/m4-x-0-7mm-nylock-nut/?sku=2812-0004-0007 | G24: Final Product
A25: Pill Chamber
B26: Adafruit Feedback 360 Degree - High Speed Continuous Rotation Servo | C26: 1 | D26: 27.99 | E26: =C26*D26 -> 27.99 | F26: https://www.adafruit.com/product/3614 | G26: Final Product
B27: 2305 Series Brass, MOD 0.8, Servo Gear (25 Tooth Spline, 30 Tooth) | C27: 1 | D27: 9.34 | E27: =C27*D27 -> 9.34 | F27: https://www.gobilda.com/2305-series-brass-mod-0-8-servo-gear-25-tooth-spline-30-tooth/ | G27: Final Product | H27: **David replaced this with the same one from gobuilda vs servo city to get the discount**
B28: 20 Degree Pressure Angle Gear Rack, 32 Pitch (1 ft) | C28: 1 | D28: 3.87 | E28: =C28*D28 -> 3.87 | F28: 20 Degree Pressure Angle Gear Rack, 32 Pitch | McMaster-Carr | G28: Final Product
B29: Funnel | C29: 1 | D29: 6.99 | E29: =C29*D29 -> 6.99 | F29: https://www.acehardware.com/departments/lawn-and-garden/outdoor-power-equipment/funnels/73094 | G29: Final Product
B30: 3D Printing of tunnel and dispenser | C30: 1 | D30: 25 | E30: =C30*D30 -> 25 | F30: EIH | G30: 3D Printed | H30: Possible plastic sheet. Use heat gun to mold into jelly bean chamber.
B31: ABS Bar Stock (1 ft Rectangular Stock) | C31: 1 | D31: 4.8 | E31: =C31*D31 -> 4.8 | F31: https://www.mcmaster.com/8712K151-8712K152/ | G31: Stock and manufacture
B32: Jelly bean chambers | C32: 2 | D32: 2.5 | E32: =C32*D32 -> 5 | F32: TBD | G32: Stock and manufacture
A33: Koozie | B33: 3D printing with ABS-M30 | C33: 2 | D33: =25 -> 25 | E33: =C33*D33 -> 50
A34: Wearable Device
B35: Thermistors | C35: 2 | D35: 0.4 | E35: =C35*D35 -> 0.8 | F35: https://www.digikey.com/en/products/detail/kyocera-avx/ND03P00333K--/1452053?gad_source=1&gad_campaignid=20682862038&gbraid=0AAAAADrbLlihpozHczm7iSeXBJ4Rpn0DV&gclid=Cj0KCQjwxL7GBhDXARIsAGOcmIMkgYX8SvMh8Ca3dpat8Z4KVMCYqJJgqFAxlJ7ChvtwJ06sXMiWvT0aAoIHEALw_wcB&gclsrc=aw.ds | G35: Final Product
B36: Button | C36: 2 | D36: 0.1 | E36: =C36*D36 -> 0.2 | F36: https://www.digikey.com/en/products/detail/omron-electronics-inc-emc-div/B3F-1020/44059?gclsrc=aw.ds&gad_source=1&gad_campaignid=20509826117&gbraid=0AAAAADrbLlgPahjgQjTiZA4NtmRxex-fT&gclid=Cj0KCQjwxL7GBhDXARIsAGOcmINhvAJ8CTcOZCDOgN0-hotT2-AahMXe-lMgYzgAD1VIPJNkVBgZdqYaAuCqEALw_wcB | G36: Final Product
B37: Wiring | C37: 4 | D37: 0.82 | E37: =C37*D37 -> 3.28 | F37: https://www.digikey.com/en/products/detail/alpha-wire/5952-BK001/3714462?gclsrc=aw.ds&gad_source=1&gad_campaignid=22518511088&gbraid=0AAAAADrbLlhVhOLGFCPlUNazu0x0ttA0s&gclid=Cj0KCQjwxL7GBhDXARIsAGOcmIPyQ8hwEqQjQgVImE37vOKvKr1mWB6dPkPzyWkGeovws5WE5QfGTfEaAvJSEALw_wcB | G37: Final Product
B38: Velcro Straps | C38: 1 | D38: 6.99 | E38: =C38*D38 -> 6.99 | F38: https://www.amazon.com/100PCS-Reusable-Cable-Ties-Multi-Purpose/dp/B08TTPX4KB/ref=sr_1_10?crid=3AO0XX6E18FN5&dib=eyJ2IjoiMSJ9.5uxKrnhwYWYlS99sRUGol5WdDjhqdalzWfPKt2coPm9nhNE3vEc5eVInBM0FTfooiWFHpSmm9fOvw-Beq1wyCURKQiIkYznaU1ppuQTLK_FlPDgm_5CxKh9iCIgekrRzAhvQl-ehlm9E4s4KKaCjVGVBE3J5bzOCHZP6HlIjtAFJRXYv2sK5PKfPL5eKLPhZsj7wAyWEihAbZhFny3Z4QOJsrYWPqYhbHs5QYQVgEUE.ssU8pSmO4YohGc3aibTPUtze_gN_xwGgPL8R6VNDW3c&dib_tag=se&keywords=thin%2Bvelcro%2Bstrap&qid=1759242218&sprefix=thin%2Bvelcro%2Bstrap%2B%2Caps%2C136&sr=8-10&th=1 | G38: Stock
B39: Nylon Webbing | C39: 1 | D39: 9.99 | E39: =C39*D39 -> 9.99 | F39: https://www.amazon.com/PerkHomy-Webbing-Lightweight-Crafting-Repairing/dp/B0DKHCGQX8/ref=sr_1_2_sspa?dib=eyJ2IjoiMSJ9.Pda-R7EW_MfioyDKuUhetgMA2FHwFgVhe2z5H8evgaLWEfyZletO3rzE4DvLlRbzNzNicZRkWMqdtVHlRo-ZgGmDj4dzN_nAeM97bQ-w0KGHj7bvXO5kFiX5Kd0ZuTd-vMPR0__KZlzj-gV8psHJ4ifzEbDCuKMR-e667sKIY5ARoBJpUitUTlr5ym80Zx-IONKJfAO_f0qXTU9lRNenKQC0VMx9zyRki75qqlED2NWcab4X8PP2aQiWBdfBtY-7mE-CowFtZnQDPZtyeXATySBtdOXNrRkWpU0ZeJlNcuc._xfHV88g0eSTFwXjG6ERn8N_P_pe6NseAzwzG_Vou40&dib_tag=se&hvadid=694130734047&hvdev=c&hvexpln=67&hvlocphy=9016261&hvnetw=g&hvocijid=4653629168605544221--&hvqmt=b&hvrand=4653629168605544221&hvtargid=kwd-2034930858&hydadcr=24634_13626630&keywords=2%2Binch%2Bnylon%2Bwebbing&mcid=2ef6ee1a3eaf34f1b0e99770c76534ec&qid=1759242049&sr=8-2-spons&sp_csd=d2lkZ2V0TmFtZT1zcF9hdGY&th=1
B40: Ladder clasp | C40: 1 | D40: 9.99 | E40: =C40*D40 -> 9.99 | F40: https://www.amazon.com/Plastic-Ladder-Adjustable-Backpack-Webbing/dp/B07X6CKF9J/ref=sr_1_8?crid=2REO62JIF6PFA&dib=eyJ2IjoiMSJ9.FBSX7gHO34VUYworgCPtvKCwvRa2ZLlRGeu0XCL2RfNBNAcTbs96EXjsrwz6S5S8rtSTd0Poa6M2HGvuoZD5vC4iWcAMByUFIPcBiNkoa43-kn94RbLg9nfIsYyNoyrbnJUuxkSAElTGKJ1WdMMOKVHWt8vSouOd5f76UZg1CSVkCrsUQQwyYVjaQoGoDog0ZkH25JUymkMYb4jHe4b_Gh08tRoFBjbcsrmHfUZVhKDz9oClDPTdokkIWP111RGBd5VThWPby2DXzyZAJtSUYCKok3zCpe2jvdV9IYLeEGE.qKpBfBWgHv0gLrdEVLP_RmnwDQYrvDuPduhLbl4L-k8&dib_tag=se&keywords=2%2Bin%2Bladder%2Block&qid=1759242412&sprefix=2%2Bin%2Bladder%2Block%2B%2Caps%2C126&sr=8-8&th=1
...

Sheet Simple
B2: System | C2: Component | D2: Links | E2: Cost (USD)
B3: Wearable Devices | C3: Thermistor x2 | D3: https://www.digikey.com/en/products/detail/kyocera-avx/ND03P00333K--/1452053?gad_source=1&gad_campaignid=20682862038&gbraid=0AAAAADrbLlihpozHczm7iSeXBJ4Rpn0DV&gclid=Cj0KCQjwxL7GBhDXARIsAGOcmIMkgYX8SvMh8Ca3dpat8Z4KVMCYqJJgqFAxlJ7ChvtwJ06sXMiWvT0aAoIHEALw_wcB&gclsrc=aw.ds | E3: =0.4*2 -> 0.8
C4: Button x2 | D4: https://www.digikey.com/en/products/detail/omron-electronics-inc-emc-div/B3F-1020/44059?gclsrc=aw.ds&gad_source=1&gad_campaignid=20509826117&gbraid=0AAAAADrbLlgPahjgQjTiZA4NtmRxex-fT&gclid=Cj0KCQjwxL7GBhDXARIsAGOcmINhvAJ8CTcOZCDOgN0-hotT2-AahMXe-lMgYzgAD1VIPJNkVBgZdqYaAuCqEALw_wcB | E4: 0.5
C5: Raspberry Pi SD card | D5: https://www.adafruit.com/product/6011 | E5: 25.58
C6: Raspberry Pi (20W) x2 | D6: https://www.amazon.com/Raspberry-Zero-Bluetooth-RPi-2W/dp/B09LH5SBPS/ref=sr_1_1?crid=IAYO9RHYYNDE&dib=eyJ2IjoiMSJ9.3BENuF2Ktu1UHOlVshSOQbzOMw-RCTR_xgvcMZPiKB_TiMbTC0Kfmvd9ccD-1WiPSfAIvORbJUCnc3B4ci0u1t34-E_YR7j7Aca9zlrt3pIhKnooj0ZaYcoEPhWQIUjfpjw6dd1Q2lY0tGYMR8zjJwyM7PBSK8LdZGx4C1BPQqfEpP0G7AuIO7iSJPEI1YfiUAh7Yf1aju6KNsxJ_xjoyk01n794R3foEM2nHxRddyNsE3UmePMEPhuILvu8b3LHXwI7KiGTo0CysIUnO6Yxv1LoCLopMta52uQvhKapzjg.xdKXkecY2uiIA-oP3PhjkSMjNbgXGQlTGpyOYGTpEws&dib_tag=se&keywords=raspberry+pi+02w&qid=1758490121&s=electronics&sprefix=raspberry+pi+02w%2Celectronics%2C111&sr=1-1 | E6: 43.82
C7: Disposable battery pack | D7: amazon.com/Powermax-24-Count-Batteries-Recloseable-Packaging/dp/B0BFFQQHRY/ref=sr_1_7?crid=349M4RTAKP3LU&dib=eyJ2IjoiMSJ9.sDk8mHya1-twxNdSRCH3uOxsUV1iruH7wiWHxBgGFYyKl3uY8UYWyDVfF4KMip1aPt2ZVJL_lywPfxiIlBhgTNbCRPPH-Q_7KX9nnbsSJ6lO_THu7adO5YgocwDSKVa6f9L2rJIgh18TOmz3GaER-UVfJMFUuslyFzbEF3JXdWutOql7wsIn1SBEIz9l6Ap2t0Q7EfCtcTYL8E4JrPx25kPJ1GRlujiqCmhkaXoJ299PELBy73ahflFJOcaGy0LUzXB-_DZw8v3W8ZvAPzs3IbupzI-kZAjLeRO8HnY646k.xKhxhNfhXkvZy7WOmhx3OiHYHpOxH-rPpamI53eGUH4&dib_tag=se&keywords=aaa+batteries&qid=1758489895&rdc=1&sprefix=aaa+batteries%2Caps%2C147&sr=8-7 | E7: 6.99
C8: Velcro straps | D8: https://www.amazon.com/WSZJINB-Reusable-Securing-Management-Organizer/dp/B09YPZBSMK/ref=ast_sto_dp_puis?th=1 | E8: 9.99
B9: Koozies | C9: Both koozies | D9: 3D Print | E9: 50
B10: Dispenser | C10: Servo | D10: https://www.adafruit.com/product/3614 | E10: 27.99
C11: Servo Gear | D11: https://www.servocity.com/2305-series-brass-mod-0-8-servo-gear-25-tooth-spline-20-tooth/ | E11: 9.99
C12: Gear Rack | D12: https://www.mcmaster.com/products/gear-racks/plastic-gears-and-gear-racks-20-pressure-angle/ | E12: 3.87
C13: Rack Guide Tunnel and Dispenser | D13: 3D print | E13: 25
C14: Pill Chambers | D14: TBD | E14: 5
C15: Gear Rack Rectangular Stock | D15: https://www.mcmaster.com/products/gear-racks/plastic-gears-and-gear-racks-20-pressure-angle/ | E15: 3.08
C16: Funnel | D16: https://www.acehardware.com/departments/lawn-and-garden/outdoor-power-equipment/funnels/73094 | E16: 6.99
B17: Drivetrain | C17: Motors x2 | D17: https://www.gobilda.com/5203-series-yellow-jacket-planetary-gear-motor-13-7-1-ratio-24mm-length-8mm-rex-shaft-435-rpm-3-3-5v-encoder/ | E17: 109.98
C18: Motor Coupler x2 | D18: https://www.gobilda.com/1309-series-sonic-hub-8mm-rex-bore/ | E18: 15.98
C19: Back Wheels x2 | D19: https://www.gobilda.com/hogback-traction-wheel-96mm-diameter-50a-durometer/ | E19: 19.98
C20: Front Wheels x2 | D20: https://www.gobilda.com/96mm-omni-wheel-14mm-bore-50a-durometer/ | E20: 43.98
C21: Motor Controller x2 | D21: https://www.gobilda.com/roboclaw-2x7a-motor-controller/ | E21: 79.99
C22: Raspberry Pi SD card | D22: https://www.adafruit.com/product/6011 | E22: 12.79
C23: Axel + Adaptor | D23: TBD | E23: 30
B24: Chassis | C24: Screws and fasteners | D24: TBD | E24: 20
C25: U-Channels 9 Hole x6 | D25: https://www.gobilda.com/1120-series-u-channel-9-hole-240mm-length/ | E25: 77.94
B26: Electronics | C26: Raspberry Pi | D26: https://www.amazon.com/Raspberry-Pi-Model-2GB/dp/B09TTNPB4J/ref=sr_1_7?crid=252TN1F58JG7S&dib=eyJ2IjoiMSJ9.HavuMzOx0pibLLpdWCmY0-n0KHJjeMikjbp58OMNJLHzsHsnrnftGjcbTUet3sVDtWfqXrWNT_k0tecU9w3FKXH2ovqggzRmNrAxzCSXAN4MIW-dVt4y_lBv65_4xWlpOFynxAc1vvqZbU0O4POhztxzEWIJLutZkLR7e5QKBxK0QEUaxvljbCqDhgi4j4SycpAX2ISoYqWR0d-ktpwasFRjYiY87Pt-06ZXpK3bbcK7ebo3Efmmhp7IM0G4TjF_fehxUl75SkZ0Lccy942LBsVlldwXyJJTAXj7OyNd4-Q.tSJdz6wDIH7He3vMiH1m9lPeU17o42S3eYchCjiuIN0&dib_tag=se&keywords=raspberry+pi+4b&qid=1758490404&s=electronics&sprefix=raspberry+pi+4b%2Celectronics%2C87&sr=1-7 | E26: 59.99
C27: Recharagable Battery | D27: https://www.horizonhobby.com/product/SPMX223S30.html?utm_source=google&utm_medium=cpc&utm_campaign=horizonhobby_shopping-catch-all_01_HIGH_NONBRAND&utm_campaignid=21803082141&adgroupid=177403203788&utm_content=717153848083&utm_term=::matchtype_&utm_campaign=horizonhobby_shopping-catch-all_01_HIGH_NONBRAND&utm_device=c&gad_source=1&gad_campaignid=21803082141&gbraid=0AAAAAD_XYFnlHiL7AuJt09DydfHVU8a5E&gclid=Cj0KCQjwxL7GBhDXARIsAGOcmIPf-NNGAqYpJERcda3UWFCJz1_7U0zTVIBhbQ2cUqwIIpjli_aaAZYaAhohEALw_wcB | E27: 23.99
C28: Fuse | D28: https://greatplainsindustries.com/products/15-amp-inline-blade-fuse-assembly?currency=USD&variant=45309174612203&utm_source=google&utm_medium=cpc&utm_campaign=Google%20Shopping&stkn=a58b0943c3a3&srsltid=AfmBOoqkjYlN-B0OjoPkA-O_3sAOCE-_kUCQOOv8S0REYq6af7ZgD4CSnPc | E28: 8
C29: Wiring | D29: https://www.digikey.com/en/products/detail/alpha-wire/5952-BK001/3714462?gclsrc=aw.ds&gad_source=1&gad_campaignid=22518511088&gbraid=0AAAAADrbLlhVhOLGFCPlUNazu0x0ttA0s&gclid=Cj0KCQjwxL7GBhDXARIsAGOcmIPyQ8hwEqQjQgVImE37vOKvKr1mWB6dPkPzyWkGeovws5WE5QfGTfEaAvJSEALw_wcB | E29: 5
B30: Total | E30: =SUM(E3:E29) -> 727.22

Sheet Simple Full name
B2: System | C2: Component | D2: Links | E2: Cost (USD)
B3: ='Detailed BOM V1'!A3 -> Drivetrain | C3: =CONCATENATE( CONCATENATE('Detailed BOM V1'!B3," x") ,'Detailed BOM V1'!C3) -> 435 RPM GoBuilda Yellow Jacket Motors x2 | D3: ='Detailed BOM V1'!F3 -> https://www.gobilda.com/5203-series-yellow-jacket-planetary-gear-motor-13-7-1-ratio-24mm-length-8mm-rex-shaft-435-rpm-3-3-5v-encoder/ | E3: ='Detailed BOM V1'!E3 -> 109.98
C4: =CONCATENATE( CONCATENATE('Detailed BOM V1'!B4," x") ,'Detailed BOM V1'!C4) -> 1309 Series Sonic Hub (8mm REX™ Bore) x2 | D4: ='Detailed BOM V1'!F4 -> https://www.gobilda.com/1309-series-sonic-hub-8mm-rex-bore/ | E4: ='Detailed BOM V1'!E4 -> 15.98
C5: =CONCATENATE( CONCATENATE('Detailed BOM V1'!B5," x") ,'Detailed BOM V1'!C5) -> Hogback Traction Wheels (Back Wheels) x2 | D5: ='Detailed BOM V1'!F5 -> https://www.gobilda.com/hogback-traction-wheel-96mm-diameter-50a-durometer/ | E5: ='Detailed BOM V1'!E5 -> 19.98
C6: =CONCATENATE( CONCATENATE('Detailed BOM V1'!B6," x") ,'Detailed BOM V1'!C6) -> RoboClaw Motor Controller x1 | D6: ='Detailed BOM V1'!F6 -> https://www.gobilda.com/roboclaw-2x15a-motor-controller/ | E6: ='Detailed BOM V1'!E6 -> 99.99
C7: =CONCATENATE( CONCATENATE('Detailed BOM V1'!B7," x") ,'Detailed BOM V1'!C7) -> 2802 Series Zinc-Plated Steel Button Head Screw (M4 x 0.7mm, 12mm Length) - 25 Pack x2 | D7: ='Detailed BOM V1'!F7 -> https://www.gobilda.com/2802-series-zinc-plated-steel-button-head-screw-m4-x-0-7mm-12mm-length-25-pack/ | E7: ='Detailed BOM V1'!E7 -> 7.18
C8: =CONCATENATE( CONCATENATE('Detailed BOM V1'!B8," x") ,'Detailed BOM V1'!C8) -> 96mm Omni Wheels (Front Wheels) x2 | D8: ='Detailed BOM V1'!F8 -> https://www.gobilda.com/96mm-omni-wheel-14mm-bore-50a-durometer/ | E8: ='Detailed BOM V1'!E8 -> 43.98
C9: =CONCATENATE( CONCATENATE('Detailed BOM V1'!B9," x") ,'Detailed BOM V1'!C9) -> Raspberry Pi 4B x1 | D9: ='Detailed BOM V1'!F9 -> https://www.amazon.com/Raspberry-Pi-Model-2GB/dp/B09TTNPB4J/ref=sr_1_7?crid=252TN1F58JG7S&dib=eyJ2IjoiMSJ9.HavuMzOx0pibLLpdWCmY0-n0KHJjeMikjbp58OMNJLHzsHsnrnftGjcbTUet3sVDtWfqXrWNT_k0tecU9w3FKXH2ovqggzRmNrAxzCSXAN4MIW-dVt4y_lBv65_4xWlpOFynxAc1vvqZbU0O4POhztxzEWIJLutZkLR7e5QKBxK0QEUaxvljbCqDhgi4j4SycpAX2ISoYqWR0d-ktpwasFRjYiY87Pt-06ZXpK3bbcK7ebo3Efmmhp7IM0G4TjF_fehxUl75SkZ0Lccy942LBsVlldwXyJJTAXj7OyNd4-Q.tSJdz6wDIH7He3vMiH1m9lPeU17o42S3eYchCjiuIN0&dib_tag=se&keywords=raspberry+pi+4b&qid=1758490404&s=electronics&sprefix=raspberry+pi+4b%2Celectronics%2C87&sr=1-7 | E9: ='Detailed BOM V1'!E9 -> 59.99
C10: =CONCATENATE( CONCATENATE('Detailed BOM V1'!B10," x") ,'Detailed BOM V1'!C10) -> Recharable Battery (STILL TBD) x1 | D10: ='Detailed BOM V1'!F10 -> https://www.horizonhobby.com/product/SPMX223S30.html?utm_source=google&utm_medium=cpc&utm_campaign=horizonhobby_shopping-catch-all_01_HIGH_NONBRAND&utm_campaignid=21803082141&adgroupid=177403203788&utm_content=717153848083&utm_term=::matchtype_&utm_campaign=horizonhobby_shopping-catch-all_01_HIGH_NONBRAND&utm_device=c&gad_source=1&gad_campaignid=21803082141&gbraid=0AAAAAD_XYFnlHiL7AuJt09DydfHVU8a5E&gclid=Cj0KCQjwxL7GBhDXARIsAGOcmIPf-NNGAqYpJERcda3UWFCJz1_7U0zTVIBhbQ2cUqwIIpjli_aaAZYaAhohEALw_wcB | E10: ='Detailed BOM V1'!E10 -> 23.99
C11: =CONCATENATE( CONCATENATE('Detailed BOM V1'!B11," x") ,'Detailed BOM V1'!C11) -> In-Line Fuse (STILL TBD) x1 | D11: ='Detailed BOM V1'!F11 -> https://greatplainsindustries.com/products/15-amp-inline-blade-fuse-assembly?currency=USD&variant=45309174612203&utm_source=google&utm_medium=cpc&utm_campaign=Google%20Shopping&stkn=a58b0943c3a3&srsltid=AfmBOoqkjYlN-B0OjoPkA-O_3sAOCE-_kUCQOOv8S0REYq6af7ZgD4CSnPc | E11: ='Detailed BOM V1'!E11 -> 7.99
C12: =CONCATENATE( CONCATENATE('Detailed BOM V1'!B12," x") ,'Detailed BOM V1'!C12) -> Raspberry Pi SD Card x1 | D12: ='Detailed BOM V1'!F12 -> https://www.amazon.com/SanDisk-Ultra-microSDHC-Memory-Adapter/dp/B0B7NXBM6P/?th=1 | E12: ='Detailed BOM V1'!E12 -> 9.99
C13: =CONCATENATE( CONCATENATE('Detailed BOM V1'!B16," x") ,'Detailed BOM V1'!C16) -> Shouldered 8mm REX™ Hub-Shaft (20mm Hub Offset) x2 | D13: ='Detailed BOM V1'!F16 -> https://www.gobilda.com/shouldered-8mm-rex-hub-shaft-20mm-hub-offset/ | E13: ='Detailed BOM V1'!E16 -> 25.98
B14: ='Detailed BOM V1'!A17 -> Chassis | C14: =CONCATENATE( CONCATENATE('Detailed BOM V1'!B17," x") ,'Detailed BOM V1'!C17) -> 1120 Series U-Channel (9 Hole, 240mm Length) x4 | D14: ='Detailed BOM V1'!F17 -> https://www.gobilda.com/1120-series-u-channel-9-hole-240mm-length/ | E14: ='Detailed BOM V1'!E17 -> 51.96
C15: =CONCATENATE( CONCATENATE('Detailed BOM V1'!B18," x") ,'Detailed BOM V1'!C18) -> M4 x 0.7mm Zinc-Plated Socket Head Screw (8mm Length) (25 Pack) x2 | D15: ='Detailed BOM V1'!F18 -> https://www.gobilda.com/m4-x-0-7mm-zinc-plated-socket-head-screw-8mm-length/ | E15: ='Detailed BOM V1'!E18 -> 6.38
C16: =CONCATENATE( CONCATENATE('Detailed BOM V1'!B22," x") ,'Detailed BOM V1'!C22) -> M4 x 0.7mm Nylock Nut (25 Pack) x2 | D16: ='Detailed BOM V1'!F22 -> https://www.gobilda.com/m4-x-0-7mm-nylock-nut/?sku=2812-0004-0007 | E16: ='Detailed BOM V1'!E22 -> 4.38
B17: Pill Dispener | C17: =CONCATENATE( CONCATENATE('Detailed BOM V1'!B24," x") ,'Detailed BOM V1'!C24) -> Parallax Feedback 360 Degree - High Speed Continuous Rotation Servo x1 | D17: ='Detailed BOM V1'!F24 -> https://www.parallax.com/product/parallax-feedback-360-high-speed-servo/ | E17: ='Detailed BOM V1'!E24 -> 27.99
C18: =CONCATENATE( CONCATENATE('Detailed BOM V1'!B25," x") ,'Detailed BOM V1'!C25) -> 2305 Series Brass, MOD 0.8, Servo Gear (25 Tooth Spline, 30 Tooth) x1 | D18: ='Detailed BOM V1'!F25 -> https://www.gobilda.com/2305-series-brass-mod-0-8-servo-gear-25-tooth-spline-30-tooth/ | E18: ='Detailed BOM V1'!E25 -> 9.99
C19: =CONCATENATE( CONCATENATE('Detailed BOM V1'!B26," x") ,'Detailed BOM V1'!C26) -> 20 Degree Pressure Angle Gear Rack, 32 Pitch (1 ft) x1 | D19: ='Detailed BOM V1'!F26 -> 20 Degree Pressure Angle Gear Rack, 32 Pitch | McMaster-Carr | E19: ='Detailed BOM V1'!E26 -> 3.87
D20: =#REF! -> #REF! | E20: =#REF! -> #REF!
C21: =CONCATENATE( CONCATENATE('Detailed BOM V1'!B27," x") ,'Detailed BOM V1'!C27) -> 3D Printing of tunnel and dispenser x1 | D21: ='Detailed BOM V1'!F27 -> EIH (tentative to change) | E21: ='Detailed BOM V1'!E27 -> 25
C22: =CONCATENATE( CONCATENATE('Detailed BOM V1'!B28," x") ,'Detailed BOM V1'!C28) -> ABS Bar Stock (1 ft) x1 | D22: ='Detailed BOM V1'!F28 -> https://www.mcmaster.com/8712K151-8712K152/ | E22: ='Detailed BOM V1'!E28 -> 4.8
C23: =CONCATENATE( CONCATENATE('Detailed BOM V1'!B29," x") ,'Detailed BOM V1'!C29) -> PETE Polyethylene Terephthalate Jelly Bean Chambers x1 | D23: ='Detailed BOM V1'!F29 -> amazon link | E23: ='Detailed BOM V1'!E29 -> 8.54
B24: ='Detailed BOM V1'!A30 -> Koozie | C24: =CONCATENATE( CONCATENATE('Detailed BOM V1'!B30," x") ,'Detailed BOM V1'!C30) -> 3D printing with ABS-M30 x2 | D24: ='Detailed BOM V1'!F30 | E24: ='Detailed BOM V1'!E30 -> 50
B25: Electronics | C25: =CONCATENATE( CONCATENATE('Detailed BOM V1'!B32," x") ,'Detailed BOM V1'!C32) -> Thermistors x2 | D25: ='Detailed BOM V1'!F32 -> https://www.digikey.com/en/products/detail/kyocera-avx/ND03P00333K--/1452053?gad_source=1&gad_campaignid=20682862038&gbraid=0AAAAADrbLlihpozHczm7iSeXBJ4Rpn0DV&gclid=Cj0KCQjwxL7GBhDXARIsAGOcmIMkgYX8SvMh8Ca3dpat8Z4KVMCYqJJgqFAxlJ7ChvtwJ06sXMiWvT0aAoIHEALw_wcB&gclsrc=aw.ds | E25: ='Detailed BOM V1'!E32 -> 0.8
C26: =CONCATENATE( CONCATENATE('Detailed BOM V1'!B33," x") ,'Detailed BOM V1'!C33) -> Button x2 | D26: ='Detailed BOM V1'!F33 -> https://www.digikey.com/en/products/detail/omron-electronics-inc-emc-div/B3F-1020/44059?gclsrc=aw.ds&gad_source=1&gad_campaignid=20509826117&gbraid=0AAAAADrbLlgPahjgQjTiZA4NtmRxex-fT&gclid=Cj0KCQjwxL7GBhDXARIsAGOcmINhvAJ8CTcOZCDOgN0-hotT2-AahMXe-lMgYzgAD1VIPJNkVBgZdqYaAuCqEALw_wcB | E26: ='Detailed BOM V1'!E33 -> 0.2
C27: =CONCATENATE( CONCATENATE('Detailed BOM V1'!B34," x") ,'Detailed BOM V1'!C34) -> Wiring x4 | D27: ='Detailed BOM V1'!F34 -> https://www.digikey.com/en/products/detail/alpha-wire/5952-BK001/3714462?gclsrc=aw.ds&gad_source=1&gad_campaignid=22518511088&gbraid=0AAAAADrbLlhVhOLGFCPlUNazu0x0ttA0s&gclid=Cj0KCQjwxL7GBhDXARIsAGOcmIPyQ8hwEqQjQgVImE37vOKvKr1mWB6dPkPzyWkGeovws5WE5QfGTfEaAvJSEALw_wcB | E27: ='Detailed BOM V1'!E34 -> 3.28
C28: =CONCATENATE( CONCATENATE('Detailed BOM V1'!B35," x") ,'Detailed BOM V1'!C35) -> Velcro Straps x1 | D28: ='Detailed BOM V1'!F35 -> https://www.walmart.com/ip/10Pcs-Buddy-Tape-Finger-Straps-Hook-Loop-Splint-Washable-Reusable-Toe-Straighteners-Curled-Toes-Support-Black/17094772032?wmlspartner=wlpa&selectedSellerId=101044658&wmlspartner=wlpa&cn=FY25-ENTP-PMAX_cnv_dps_dsn_dis_ad_entp_e_n&gclsrc=aw.ds&adid=2222222229717094772032_101044658_0000000000_21407473164&wl0=&wl1=x&wl2=c&wl3=&wl4=&wl5=1017248&wl6=&wl7=&wl8=&wl9=pla&wl10=276374024&wl11=online&wl12=17094772032_101044658&veh=sem&gad_source=1&gad_campaignid=21690411341&gbraid=0AAAAADmfBIop_VMkZGxGUztXQNDLx5Xnb&gclid=Cj0KCQjw0NPGBhCDARIsAGAzpp09Hj-D8jirZ63Fy1QZetg9nVV2-cplttCXt_YcEuHNL-o4IEu5McAaAtNCEALw_wcB | E28: ='Detailed BOM V1'!E35 -> 12.99
C29: =CONCATENATE( CONCATENATE('Detailed BOM V1'!B38," x") ,'Detailed BOM V1'!C38) -> Build-A-Board ESP32-C3 x2 | D29: ='Detailed BOM V1'!F38 -> Got from EIH | E29: ='Detailed BOM V1'!E38 -> 40
C30: =CONCATENATE( CONCATENATE(#REF!," x") ,#REF!) -> #REF! | D30: =#REF! -> #REF! | E30: =#REF! -> #REF!
C31: =CONCATENATE( CONCATENATE('Detailed BOM V1'!B40," x") ,'Detailed BOM V1'!C40) -> 9V Battery (4 pack) x1 | D31: ='Detailed BOM V1'!F40 -> https://www.amazon.com/Quzmo-Rechargeable-Lithium-ion-Multimeters-Walkie-Talkie/dp/B0CRYBR876/ref=sr_1_6?dib=eyJ2IjoiMSJ9.AmbU2iWIJWmLrdxVTAnt282MGmjVjs086-2SWVfqZnUfPSwxeMfoGCBT6SzW_7msjsup7AEWUH9MjT7tZ4_8t0e9bolrgquHKyWZT5A79-VKktdHt-M5pSd1f2b24tdsbSC78NrPuV6_JL922AFxPWZNqUrCuq_hqDJ6fj46bDLilJ9e8B4Bfk9xByyp0NS6aKSSNoELk0ilNJu4eAaXr1C_sMkjAC1XTYVv4dyhExVyirpApBgoKmCeQK3opRM8v91XH6q70dIAgzv6DoR6nx5-5YE_TKO7Zjq-qrkVvdI.xeV7tGChITYND5UcpClBXA_y0Mxs-iZG48akDr7FHR4&dib_tag=se&keywords=9v%2Blithium%2Brechargeable%2Bbattery&qid=1758642638&sr=8-6&th=1 | E31: ='Detailed BOM V1'!E40 -> 18.99
B32: ='Detailed BOM V1'!A42 -> Total | D32: ='Detailed BOM V1'!F42 | E32: ='Detailed BOM V1'!E42 -> 783.64
